<?xml version="1.0" ?>
<robot name="Jeevan">
  

  <!-- Base -->
  <link name="base_footprint">
    <visual>
      <origin xyz="0. 0.0 0.15" rpy="0.0 0.0 0.0"/>
      <geometry>
          <box size="0.1 0.1 0.1"/>
      </geometry>
    </visual>
  </link>

  <joint name="base_joint" type="fixed">
    <parent link="base_footprint"/>
    <child link="base_link"/>
    <origin xyz="-0.15 0.0 0.15" rpy="0.0 0.0 0.0"/>
  </joint>

  <link name="base_link"><!-- Chassi Joint -->
    <visual>
      <origin xyz="0.325 0.0 0.0" rpy="0.0 0.0 0.0"/>
      <geometry>
          <box size="0.75 0.4 0.1"/>
      </geometry>
      <material name="gray"> <!-- CHASSI -->
        <color rgba=".2 .2 .2 1" />
      </material>
    </visual>
    
    <collision>
      <origin xyz="0.325 0.0 0.0" rpy="0.0 0.0 0.0"/>     
      <geometry>
          <box size="0.75 0.4 0.1"/>
      </geometry>
    </collision>

    <inertial>
      <mass value="1" />
      <inertia ixx="0.01" ixy="0.0" ixz="0" 
      iyy="0.01" iyz="0" izz="0.01" />
    </inertial>
    
  </link>

  <link name="wheel_right_link">
    <inertial>
            <mass value="1" />
            <inertia ixx="0.01" ixy="0.0" ixz="0" 
            iyy="0.01" iyz="0" izz="0.01" />
    </inertial>

    <visual>
      <origin xyz="0.0 0.0 0.0" rpy="0.0 0.0 0.0"/>
      <geometry>
          <cylinder radius="0.15" length="0.1"/>
      </geometry>
      <material name="black"> <!-- WHEELS -->
        <color rgba = "0 0 0 1"/>
      </material>
    </visual>

    <collision>
      <origin xyz="0. 0.0 0.0" rpy="0.0 0.0 0.0"/>
      <geometry>
          <cylinder radius="0.15" length="0.1"/>
      </geometry>
      <surface>
        <friction>
          <ode>
            <mu>0</mu>
            <mu2>0</mu2>
            <slip1>1.0</slip1>
            <slip2>1.0</slip2>
          </ode>
        </friction>
      </surface>
      <contact_coefficients mu="1" kp="1e+13" kd="1.0"/>
    </collision>
  </link>

  <joint name="wheel_right_joint" type="continuous">
    <parent link="base_footprint"/>
    <child link="wheel_right_link"/>
    <origin xyz="0 -0.25 0.15" rpy="-1.57 0.0 0.0"/>
    <axis xyz="0.0 0.0 1.0"/>
  </joint>

  <link name="wheel_left_link">
    <inertial>
            <mass value="2" />
            <inertia ixx="0.01" ixy="0.0" ixz="0" 
            iyy="0.01" iyz="0" izz="0.01" />
    </inertial>

    <visual>
      <origin xyz="0.0 0.0 0.0" rpy="0.0 0.0 0.0"/>
      <geometry>
          <cylinder radius="0.15" length="0.1"/>
      </geometry>
      <material name="black"> <!-- WHEELS -->
        <color rgba = "0 0 0 1"/>
      </material>
    </visual>

    <collision>
      <origin xyz="0.0 0.0 0.0" rpy="0.0 0.0 0.0"/>
      <geometry>
          <cylinder radius="0.15" length="0.1"/>
      </geometry>
      <surface>
        <friction>
          <ode>
            <mu>0</mu>
            <mu2>0</mu2>
            <slip1>1.0</slip1>
            <slip2>1.0</slip2>
          </ode>
        </friction>
      </surface>
      <contact_coefficients mu="1" kp="1e+13" kd="1.0"/>
    </collision>
  </link>

  <joint name="wheel_left_joint" type="continuous">
    <origin xyz="0. 0.25 0.15" rpy="-1.57 0.0 0.0"/>
    <parent link="base_footprint"/>
    <child link="wheel_left_link"/>
    <axis xyz="0.0 0.0 1.0"/>
  </joint>

  <link name="caster">
    <inertial>
            <mass value="1" />
            <inertia ixx="0.01" ixy="0.0" ixz="0" 
            iyy="0.01" iyz="0" izz="0.01" />
    </inertial>

    <visual>
      <geometry>
        <sphere radius="0.081" />
      </geometry>
      <material name = "blue"> <!-- CASTER -->
        <color rgba = "0.2 0.2 1 1"/>
      </material> 
    </visual>

    <collision>
      <geometry>
        <sphere radius="0.081" />
      </geometry>
      <surface>
        <friction>
          <ode>
            <mu>0</mu>
            <mu2>0</mu2>
            <slip1>1.0</slip1>
            <slip2>1.0</slip2>
          </ode>
        </friction>
      </surface>
      <contact_coefficients mu="1" kp="1e+13" kd="1.0"/>
    </collision>
  </link>

  <joint name="caster_joint" type="continuous">
    <origin xyz="0.45 0.0 0.076" rpy="0.0 0.0 0.0"/>
    <axis xyz="0 0 1" />
    <parent link="base_footprint"/>
    <child link="caster"/>
  </joint>

  <!-- laser -->
  <link name="laser">
    <inertial>
            <mass value="1" />
            <inertia ixx="0.01" ixy="0.0" ixz="0" 
            iyy="0.01" iyz="0" izz="0.01" />
    </inertial>

    <visual>
      <geometry>
        <cylinder radius="0.05" length="0.05"/> 
      </geometry>
      <material name="white"> <!-- CAMERA -->
        <color rgba = "1 1 1 1"/>
      </material>
    </visual>

    <collision>
      <origin/>
      <geometry>
        <sphere radius=".08" />
      </geometry>
    </collision>
  </link>

  <joint name="laser_joint" type="fixed">
    <origin xyz="0.525 0.0 0.225" rpy="0.0 0.0 0.0"/>
    <axis xyz="0 0 1" />
    <parent link="base_footprint"/>
    <child link="laser"/>
  </joint>

  <!-- Gazebo colors to links as upper defined colors are only visible in RVIZ-->
  <gazebo>
  <material name="white"> <color rgba = "1 1 1 1"/> </material>
  </gazebo>

  <material name="gray"> <color rgba=".2 .2 .2 1"/> </material>

  <gazebo>
  <material name="black"> <color rgba = "0 0 0 1"/> </material>
  </gazebo>
  <gazebo>
  <material name="black"> <color rgba = "0 0 0 1"/> </material>
  </gazebo>
  <gazebo>
  <material name="blue"> <color rgba = "0.2 0.2 1 1"/> </material>  
  </gazebo>
  <gazebo>
  <material name = "brown"> <color rgba = "0.6 0.4 0 1"/> </material> 
  </gazebo>
  <!-- DIFFENERNTIAL DRIVEEEEEEEEEEEEE -->
  <gazebo>
    <plugin name="gazebo_ros_control" filename="libgazebo_ros_control.so">
      <robotNamespace>/</robotNamespace>
      <controlPeriod>0.001</controlPeriod>
      <legacyModelNS>false</legacyModelNS>
    </plugin>
  </gazebo>
  
  <gazebo>
    <plugin name="differential_drive_controller" filename="libgazebo_ros_diff_drive.so">
      <legacyMode>false</legacyMode>
      <alwaysOn>true</alwaysOn>
      <updateRate>10.0</updateRate>
      <leftJoint>wheel_left_joint</leftJoint>
      <rightJoint>wheel_right_joint</rightJoint>
      <wheelSeparation>0.5</wheelSeparation>
      <wheelDiameter>0.3</wheelDiameter>
      <wheelTorque>100</wheelTorque>
      <publishTf>1</publishTf>
      <odometryFrame>odom</odometryFrame>
      <commandTopic>cmd_vel</commandTopic>
      <odometryTopic>odom</odometryTopic>
      <publishOdomTF>true</publishOdomTF>
      <robotBaseFrame>base_footprint</robotBaseFrame>
      <wheelAcceleration>5</wheelAcceleration>
      <publishWheelJointState>false</publishWheelJointState>
      <publishWheelTF>true</publishWheelTF>
      <odometrySource>odom</odometrySource>
      <rosDebugLevel>Debug</rosDebugLevel>
    </plugin>
  </gazebo>

  <gazebo>
    <plugin name="joint_state_publisher" filename="libgazebo_ros_joint_state_publisher.so">
      <jointName>caster_joint</jointName>
      <updateRate>10</updateRate>
    </plugin>
  </gazebo>

  <!-- laser plugin -->
  <gazebo reference="laser">
    <sensor type="ray" name="Lidar">
      <always_on>true</always_on>
      <pose>0 0 0 0 0 0</pose>
      <visualize>true</visualize>
      <update_rate>10</update_rate>
      <ray>
          <scan>
              <horizontal>
                  <samples>720</samples>
                  <resolution>1</resolution>
                  <min_angle>-1.57</min_angle>
                  <max_angle>1.57</max_angle>
              </horizontal>
          </scan>
          <range>
              <min>0.1</min>
              <max>50</max>
              <resolution>0.1</resolution>
          </range>
      </ray>
      <plugin name="laser" filename="libgazebo_ros_laser.so">
          <topicName>/scan</topicName>
          <frameName>laser</frameName>
      </plugin>
    </sensor>
  </gazebo>

  <!-- Camera-->
  <link name="camera_link">
    <inertia>
        
        <mass value = "0.05"/>
        <inertia ixx="0.1" ixy="0.0" ixz="0.0" iyy="0.1" iyz="0.0" izz="0.1"/>
    </inertia>
    <visual>
        
        <geometry>
            <box size="0.05 0.05 0.05"/>
        </geometry>
        <material name = "brown"> <!-- LiDAR-->
          <color rgba = "0.6 0.4 0 1"/>
        </material> 
    </visual>
    <collision>
        <origin xyz="0.0 0.0 0.0" rpy="0.0 0.0 0.0"/>
        
        <geometry>
            <box size="0.05 0.05 0.05"/>
        </geometry>            
    </collision>
  </link>

  <joint name="camera_joint" type="fixed">
    <axis xyz="0.0 0.0 0.0"/>        
    <parent link="base_footprint"/>
    <child link="camera_link"/>
    <origin xyz="0.545 0 0.275" rpy="0 0 0"/>
  </joint>

  <!-- camera -->
  <gazebo reference="camera_link">
    <sensor type="camera" name="camera1">
      <update_rate>10.0</update_rate>
      <camera name="head">
        <horizontal_fov>1.3962634</horizontal_fov>
        <image>
          <width>720</width>
          <height>720</height>
          <format>R8G8B8</format>
        </image>
        <clip>
          <near>0.02</near>
          <far>300</far>
        </clip>
        <noise>
          <type>gaussian</type>
          <!-- Noise is sampled independently per pixel on each frame.
              That pixel's noise value is added to each of its color
              channels, which at that point lie in the range [0,1]. -->
          <mean>0.0</mean>
          <stddev>0.000007</stddev>
        </noise>
      </camera>
      <plugin name="camera_controller" filename="libgazebo_ros_camera.so">
        <alwaysOn>true</alwaysOn>
        <updateRate>0.0</updateRate>
        <cameraName>camera1</cameraName>
        <imageTopicName>/image_raw</imageTopicName>
        <cameraInfoTopicName>/camera_info</cameraInfoTopicName>
        <frameName>camera_link</frameName>
        <hackBaseline>0.07</hackBaseline>
        <distortionK1>0.0</distortionK1>
        <distortionK2>0.0</distortionK2>
        <distortionK3>0.0</distortionK3>
        <distortionT1>0.0</distortionT1>
        <distortionT2>0.0</distortionT2>
      </plugin>
    </sensor>
  </gazebo>
</robot>
